<?xml version="1.0"?>
<robot name="roboworks"><link name="base_link" /><link name="chassis"><visual><geometry><mesh filename="meshes/chassis.dae" /></geometry><origin xyz="0 0 0" rpy="1.5707 0 0" /></visual></link><link name="front_left_wheel"><visual><geometry><mesh filename="meshes/wheel.dae" /></geometry></visual></link><link name="front_left_tire"><visual><geometry><mesh filename="meshes/tire.dae" /></geometry></visual></link><link name="front_right_wheel"><visual><geometry><mesh filename="meshes/wheel.dae" /></geometry><origin xyz="0 0 0" rpy="-3.1415 0 0" /></visual></link><link name="front_right_tire"><visual><geometry><mesh filename="meshes/tire.dae" /></geometry></visual></link><link name="rear_left_wheel"><visual><geometry><mesh filename="meshes/wheel.dae" /></geometry></visual></link><link name="rear_left_tire"><visual><geometry><mesh filename="meshes/tire.dae" /></geometry></visual></link><link name="rear_right_wheel"><visual><geometry><mesh filename="meshes/wheel.dae" /></geometry><origin xyz="0 0 0" rpy="3.1415 0 0" /></visual></link><link name="rear_right_tire"><visual><geometry><mesh filename="meshes/tire.dae" /></geometry></visual></link><link name="front_left_wheel_steering_link" /><link name="front_right_wheel_steering_link" /><link name="camera_link" /><link name="laser" /><link name="lidar_link" /><link name="imu_link" /><joint name="imu_joint" type="fixed"><parent link="base_link" /><child link="imu_link" /></joint><joint name="camera_joint" type="fixed"><parent link="base_link" /><child link="camera_link" /></joint><joint name="lidar_frame_joint" type="fixed"><parent link="base_link" /><child link="laser" /></joint><joint name="base_link_joint" type="fixed"><parent link="base_link" /><child link="chassis" /></joint><joint name="lidar_joint" type="fixed"><parent link="base_link" /><child link="lidar_link" /></joint><joint name="front_left_wheel_tire_joint" type="fixed"><parent link="front_left_wheel" /><child link="front_left_tire" /></joint><joint name="rear_left_wheel_tire_joint" type="fixed"><parent link="rear_left_wheel" /><child link="rear_left_tire" /></joint><joint name="front_right_wheel_tire_joint" type="fixed"><parent link="front_right_wheel" /><child link="front_right_tire" /></joint><joint name="rear_right_wheel_tire_joint" type="fixed"><parent link="rear_right_wheel" /><child link="rear_right_tire" /></joint><joint name="front_left_wheel_steering_joint" type="revolute"><parent link="base_link" /><child link="front_left_wheel_steering_link" /><axis xyz="0 0 1" /><limit lower="-0.6" upper="0.6" effort="25" velocity="1.0" /></joint><joint name="front_right_wheel_steering_joint" type="revolute"><parent link="base_link" /><child link="front_right_wheel_steering_link" /><axis xyz="0 0 1" /><limit lower="-0.6" upper="0.6" effort="25" velocity="1.0" /></joint><joint name="front_left_wheel_joint" type="revolute"><parent link="front_left_wheel_steering_link" /><child link="front_left_wheel" /><axis xyz="0 0 1" /><limit lower="-1.79769e+308" upper="1.79769e+308" effort="0" velocity="0" /></joint><joint name="front_right_wheel_joint" type="revolute"><parent link="front_right_wheel_steering_link" /><child link="front_right_wheel" /><axis xyz="0 0 1" /><limit lower="-1.79769e+308" upper="1.79769e+308" effort="0" velocity="0" /></joint><joint name="rear_left_wheel_joint" type="revolute"><parent link="base_link" /><child link="rear_left_wheel" /><axis xyz="0 0 1" /><limit lower="-1.79769e+308" upper="1.79769e+308" effort="0" velocity="0" /></joint><joint name="rear_right_wheel_joint" type="revolute"><parent link="base_link" /><child link="rear_right_wheel" /><axis xyz="0 0 1" /><limit lower="-1.79769e+308" upper="1.79769e+308" effort="0" velocity="0" /></joint></robot>