<?xml version='1.0'?>
<sdf version='1.9'>
  <model name='wheeltec'>
    <pose>0 0 0.12 0 0 0</pose>
    <static>false</static>

    <link name='base_link'>
      <inertial>
        <mass>8.0</mass>
        <inertia>
          <ixx>0.15</ixx>
          <ixy>0.0</ixy>
          <ixz>0.0</ixz>
          <iyy>0.20</iyy>
          <iyz>0.0</iyz>
          <izz>0.18</izz>
        </inertia>
      </inertial>
      <collision name='base_collision'>
        <geometry>
          <box><size>0.34 0.24 0.10</size></box>
        </geometry>
      </collision>
      <visual name='base_visual'>
        <geometry>
          <box><size>0.34 0.24 0.10</size></box>
        </geometry>
        <material>
          <ambient>0.15 0.15 0.18 1</ambient>
          <diffuse>0.25 0.25 0.30 1</diffuse>
        </material>
      </visual>
    </link>

    <link name='left_wheel_link'>
      <pose>0 0.14 -0.03 0 1.57079632679 0</pose>
      <inertial>
        <mass>0.6</mass>
        <inertia>
          <ixx>0.01</ixx>
          <ixy>0.0</ixy>
          <ixz>0.0</ixz>
          <iyy>0.01</iyy>
          <iyz>0.0</iyz>
          <izz>0.01</izz>
        </inertia>
      </inertial>
      <collision name='left_wheel_collision'>
        <geometry>
          <cylinder>
            <radius>0.035</radius>
            <length>0.025</length>
          </cylinder>
        </geometry>
      </collision>
      <visual name='left_wheel_visual'>
        <geometry>
          <cylinder>
            <radius>0.035</radius>
            <length>0.025</length>
          </cylinder>
        </geometry>
        <material>
          <ambient>0.05 0.05 0.05 1</ambient>
          <diffuse>0.05 0.05 0.05 1</diffuse>
        </material>
      </visual>
    </link>

    <link name='right_wheel_link'>
      <pose>0 -0.14 -0.03 0 1.57079632679 0</pose>
      <inertial>
        <mass>0.6</mass>
        <inertia>
          <ixx>0.01</ixx>
          <ixy>0.0</ixy>
          <ixz>0.0</ixz>
          <iyy>0.01</iyy>
          <iyz>0.0</iyz>
          <izz>0.01</izz>
        </inertia>
      </inertial>
      <collision name='right_wheel_collision'>
        <geometry>
          <cylinder>
            <radius>0.035</radius>
            <length>0.025</length>
          </cylinder>
        </geometry>
      </collision>
      <visual name='right_wheel_visual'>
        <geometry>
          <cylinder>
            <radius>0.035</radius>
            <length>0.025</length>
          </cylinder>
        </geometry>
        <material>
          <ambient>0.05 0.05 0.05 1</ambient>
          <diffuse>0.05 0.05 0.05 1</diffuse>
        </material>
      </visual>
    </link>

    <link name='lidar_link'>
      <pose>0.05 0 0.12 0 0 0</pose>
      <collision name='lidar_collision'>
        <geometry>
          <box><size>0.05 0.05 0.05</size></box>
        </geometry>
      </collision>
      <visual name='lidar_visual'>
        <geometry>
          <box><size>0.05 0.05 0.05</size></box>
        </geometry>
        <material>
          <ambient>0.15 0.55 0.15 1</ambient>
          <diffuse>0.15 0.55 0.15 1</diffuse>
        </material>
      </visual>
      <sensor name='lidar' type='lidar'>
        <always_on>true</always_on>
        <update_rate>10</update_rate>
        <visualize>true</visualize>
        <topic>scan</topic>
        <lidar>
          <scan>
            <horizontal>
              <samples>360</samples>
              <resolution>1</resolution>
              <min_angle>-3.14159265359</min_angle>
              <max_angle>3.14159265359</max_angle>
            </horizontal>
          </scan>
          <range>
            <min>0.15</min>
            <max>8.0</max>
            <resolution>0.01</resolution>
          </range>
        </lidar>
      </sensor>
    </link>

    <joint name='left_wheel_joint' type='revolute'>
      <parent>base_link</parent>
      <child>left_wheel_link</child>
      <axis>
        <xyz>0 1 0</xyz>
        <limit>
          <lower>-1e16</lower>
          <upper>1e16</upper>
        </limit>
      </axis>
    </joint>

    <joint name='right_wheel_joint' type='revolute'>
      <parent>base_link</parent>
      <child>right_wheel_link</child>
      <axis>
        <xyz>0 1 0</xyz>
        <limit>
          <lower>-1e16</lower>
          <upper>1e16</upper>
        </limit>
      </axis>
    </joint>

    <joint name='lidar_joint' type='fixed'>
      <parent>base_link</parent>
      <child>lidar_link</child>
    </joint>

    <plugin filename='gz-sim-diff-drive-system' name='gz::sim::systems::DiffDrive'>
      <left_joint>left_wheel_joint</left_joint>
      <right_joint>right_wheel_joint</right_joint>
      <wheel_separation>0.28</wheel_separation>
      <wheel_radius>0.035</wheel_radius>
      <topic>cmd_vel</topic>
      <odom_topic>odometry</odom_topic>
      <frame_id>odom</frame_id>
      <child_frame_id>base_link</child_frame_id>
    </plugin>

    <plugin filename='gz-sim-joint-state-publisher-system' name='gz::sim::systems::JointStatePublisher'/>
  </model>
</sdf>
